<?xml version="1.0" ?>
<testsuite errors="1" failures="0" name="Test_Class-20210405104024" tests="10" time="0.147">
	<testcase classname="Test_Class" name="test_Commom_Utils" time="0.004"/>
	<testcase classname="Test_Class" name="test_Google_Babynames" time="0.005"/>
	<testcase classname="Test_Class" name="test_Google_Exercise_1" time="0.007"/>
	<testcase classname="Test_Class" name="test_Google_Exercise_2" time="0.009"/>
	<testcase classname="Test_Class" name="test_Google_Exercise_3" time="0.024"/>
	<testcase classname="Test_Class" name="test_Google_Exercise_4" time="0.014"/>
	<testcase classname="Test_Class" name="test_Google_Exercise_5" time="0.018"/>
	<testcase classname="Test_Class" name="test_Google_Exercise_6" time="0.028"/>
	<testcase classname="Test_Class" name="test_Python_Pytest" time="0.012"/>
	<testcase classname="Test_Class" name="test_Python_OOP" time="0.027">
		<error message="" type="AssertionError">
<![CDATA[Traceback (most recent call last):
  File "/home/sarth/Python_Exercises_Test_Jenkins/Test_Wrapper.py", line 66, in test_Python_OOP
    assert sum == 10
AssertionError
]]>		</error>
	</testcase>
	<system-out>
<![CDATA[...............Common Utils Test Completed................
...............Google Test Completed................
...............Pytest Test Completed................
]]>	</system-out>
	<system-err>
<![CDATA[]]>	</system-err>
</testsuite>
